<?xml version="1.0"?>


<robot name="custom_gripper" xmlns:xacro="http://ros.org/wiki/xacro">
    <xacro:property name="M_PI" value="3.14159"/>
    
    <xacro:macro name="load_gripper" params="parent">  

	<material name="black">
	    <color rgba="0 0 0 1"/>
	  </material>     
        
        <joint name="gripper_base_joint" type="fixed">
            <parent link="${parent}"/>
            <child link="gripper_base_link"/>
            <origin rpy="1.57 -1.57 0.0" xyz="0.0 0.0 -0.007"/>
        </joint>
        
        
        <link name="gripper_base_link">
            <visual>
                <geometry>
                    <mesh filename="package://kortex_gazebo_camera/grippers/custom/meshes/custom_gripper_base.stl" scale="0.001 0.001 0.001"/>
                </geometry>
		<material name="black"/>
            </visual>
            <collision>
                <geometry>
                    <mesh filename="package://kortex_gazebo_camera/grippers/custom/meshes/custom_gripper_base.stl" scale="0.001 0.001 0.001"/>
                </geometry>
            </collision>
            <inertial>
                <mass value="0.636951" />
                <origin xyz="0.0 0.0 0.0" />
                <inertia ixx = "0.000380" ixy = "0.000000" ixz = "0.000000"
                         iyx = "0.000000" iyy = "0.001110" iyz = "0.000000"
                         izx = "0.000000" izy = "0.000000" izz = "0.001171" />
            </inertial>
        </link>

        <gazebo reference="gripper_base_link">
            <implicitSpringDamper>1</implicitSpringDamper>
            <mu1>100000</mu1>
            <mu2>100000</mu2>
            <kp>100000000.0</kp>
            <kd>1.0</kd>
	    <material>Gazebo/DarkGrey</material>
        </gazebo>   

        <joint name="gripper_finger1_joint" type="prismatic">
            <parent link="gripper_base_link"/>
            <child link="gripper_finger1_finger_tip_link"/>
            <axis xyz="0 1 0"/>
            <origin rpy="${M_PI} 0.0 0.0" xyz="0.05490451627 0.05060114443 0.0"/>
            <limit lower="0.0" upper="0.06" velocity="2.0" effort="1000"/>
	    <dynamics damping="1.0"       />
        </joint>

        <joint name="gripper_finger2_joint" type="prismatic">
            <parent link="gripper_base_link"/>
            <child link="gripper_finger2_finger_tip_link"/>
            <axis xyz="0 1 0"/>
            <origin rpy="0.0 0.0 0.0" xyz="0.05490451627 -0.05060114443 0.0"/>
            <limit lower="0.0" upper="0.06" velocity="2.0" effort="1000"/>
            <mimic joint="gripper_finger1_joint" multiplier="1.0"/>
	    <dynamics damping="1.0"       />
        </joint>

        <link name="gripper_finger1_finger_tip_link">
            <visual>
		<origin xyz="0.05 0 0" rpy="0 0 0" />
                <geometry>
                    <mesh filename="package://kortex_gazebo_camera/grippers/custom/meshes/custom_gripper_finger.stl" scale="0.001 0.001 0.001"/>
                </geometry>
		<material name="black"/>
            </visual>
            <collision>
		<origin xyz="0.05 0 0" rpy="0 0 0" />
                <geometry>
                    <mesh filename="package://kortex_gazebo_camera/grippers/custom/meshes/custom_gripper_finger.stl" scale="0.001 0.001 0.001"/>
                </geometry>
            </collision>
            <inertial>
                <mass value="0.019555" />
                <origin xyz="0.0 0.0 0.0" />
                <inertia ixx = "0.000002" ixy = "0.000000" ixz = "0.000000"
                         iyx = "0.000000" iyy = "0.000005" iyz = "0.000000"
                         izx = "0.000000" izy = "0.000000" izz = "0.000006" />
            </inertial>
        </link> 
        
        <gazebo reference="gripper_finger1_finger_tip_link">
            <implicitSpringDamper>1</implicitSpringDamper>
            <mu1>100000</mu1>
            <mu2>100000</mu2>
            <kp>100000000.0</kp>
            <kd>1.0</kd>
	    <material>Gazebo/DarkGrey</material>
        </gazebo> 

        <link name="gripper_finger2_finger_tip_link">
            <visual>
 		<origin xyz="0.05 0 0" rpy="0 0 0" />
                <geometry>
                    <mesh filename="package://kortex_gazebo_camera/grippers/custom/meshes/custom_gripper_finger.stl" scale="0.001 0.001 0.001"/>
                </geometry>
		<material name="black"/>
            </visual>
            <collision>
 		<origin xyz="0.05 0 0" rpy="0 0 0" />
                <geometry>
                    <mesh filename="package://kortex_gazebo_camera/grippers/custom/meshes/custom_gripper_finger.stl" scale="0.001 0.001 0.001"/>
                </geometry>
            </collision>
            <inertial>
                <mass value="0.019555" />
                <origin xyz="0.0 0.0 0.0" />
                <inertia ixx = "0.000002" ixy = "0.000000" ixz = "0.000000"
                         iyx = "0.000000" iyy = "0.000005" iyz = "0.000000"
                         izx = "0.000000" izy = "0.000000" izz = "0.000006" />
            </inertial>
        </link>
        
        <gazebo reference="gripper_finger2_finger_tip_link">
            <implicitSpringDamper>1</implicitSpringDamper>
            <mu1>100000</mu1>
            <mu2>100000</mu2>
            <kp>100000000.0</kp>
            <kd>1.0</kd>
	    <material>Gazebo/DarkGrey</material>
        </gazebo> 
        
    </xacro:macro>
</robot>
